
Setting up data pipeline
Restric
Virtual devices cannot be modified after being initialized
Epoch 1/128
2022-05-28 01:10:40.755004: E tensorflow/stream_executor/cuda/cuda_dnn.cc:371] Could not create cudnn handle: CUDNN_STATUS_NOT_INITIALIZED
2022-05-28 01:10:40.755478: E tensorflow/stream_executor/cuda/cuda_dnn.cc:379] Possibly insufficient driver version: 515.43.4
2022-05-28 01:10:40.990661: W tensorflow/core/framework/op_kernel.cc:1745] OP_REQUIRES failed at conv_ops.cc:1120 : UNKNOWN: Failed to get convolution algorithm. This is probably because cuDNN failed to initialize, so try looking to see if a warning log message was printed above.
Traceback (most recent call last):
  File "main.py", line 58, in <module>
    model_history = model.fit(
  File "/home/melih/anaconda3/envs/tf-web/lib/python3.8/site-packages/keras/utils/traceback_utils.py", line 67, in error_handler
    raise e.with_traceback(filtered_tb) from None
  File "/home/melih/anaconda3/envs/tf-web/lib/python3.8/site-packages/tensorflow/python/eager/execute.py", line 58, in quick_execute
    tensors = pywrap_tfe.TFE_Py_Execute(ctx._handle, device_name, op_name,
tensorflow.python.framework.errors_impl.UnknownError:  Failed to get convolution algorithm. This is probably because cuDNN failed to initialize, so try looking to see if a warning log message was printed above.
	 [[node model_1/model/Conv1/Conv2D
 (defined at /home/melih/anaconda3/envs/tf-web/lib/python3.8/site-packages/keras/layers/convolutional.py:231)
]] [Op:__inference_train_function_9837]
Errors may have originated from an input operation.
Input Source operations connected to node model_1/model/Conv1/Conv2D:
In[0] IteratorGetNext (defined at /home/melih/anaconda3/envs/tf-web/lib/python3.8/site-packages/keras/engine/training.py:866)	
In[1] model_1/model/Conv1/Conv2D/ReadVariableOp:
Operation defined at: (most recent call last)
>>>   File "main.py", line 58, in <module>
>>>     model_history = model.fit(
>>>
>>>   File "/home/melih/anaconda3/envs/tf-web/lib/python3.8/site-packages/keras/utils/traceback_utils.py", line 64, in error_handler
>>>     return fn(*args, **kwargs)
>>>
>>>   File "/home/melih/anaconda3/envs/tf-web/lib/python3.8/site-packages/keras/engine/training.py", line 1216, in fit
>>>     tmp_logs = self.train_function(iterator)
>>>
>>>   File "/home/melih/anaconda3/envs/tf-web/lib/python3.8/site-packages/keras/engine/training.py", line 878, in train_function
>>>     return step_function(self, iterator)
>>>
>>>   File "/home/melih/anaconda3/envs/tf-web/lib/python3.8/site-packages/keras/engine/training.py", line 867, in step_function
>>>     outputs = model.distribute_strategy.run(run_step, args=(data,))
>>>
>>>   File "/home/melih/anaconda3/envs/tf-web/lib/python3.8/site-packages/keras/engine/training.py", line 860, in run_step
>>>     outputs = model.train_step(data)
>>>
>>>   File "/home/melih/anaconda3/envs/tf-web/lib/python3.8/site-packages/keras/engine/training.py", line 808, in train_step
>>>     y_pred = self(x, training=True)
>>>
>>>   File "/home/melih/anaconda3/envs/tf-web/lib/python3.8/site-packages/keras/utils/traceback_utils.py", line 64, in error_handler
>>>     return fn(*args, **kwargs)
>>>
>>>   File "/home/melih/anaconda3/envs/tf-web/lib/python3.8/site-packages/keras/engine/base_layer.py", line 1083, in __call__
>>>     outputs = call_fn(inputs, *args, **kwargs)
>>>
>>>   File "/home/melih/anaconda3/envs/tf-web/lib/python3.8/site-packages/keras/utils/traceback_utils.py", line 92, in error_handler
>>>     return fn(*args, **kwargs)
>>>
>>>   File "/home/melih/anaconda3/envs/tf-web/lib/python3.8/site-packages/keras/engine/functional.py", line 451, in call
>>>     return self._run_internal_graph(
>>>
>>>   File "/home/melih/anaconda3/envs/tf-web/lib/python3.8/site-packages/keras/engine/functional.py", line 589, in _run_internal_graph
>>>     outputs = node.layer(*args, **kwargs)
>>>
>>>   File "/home/melih/anaconda3/envs/tf-web/lib/python3.8/site-packages/keras/utils/traceback_utils.py", line 64, in error_handler
>>>     return fn(*args, **kwargs)
>>>
>>>   File "/home/melih/anaconda3/envs/tf-web/lib/python3.8/site-packages/keras/engine/base_layer.py", line 1083, in __call__
>>>     outputs = call_fn(inputs, *args, **kwargs)
>>>
>>>   File "/home/melih/anaconda3/envs/tf-web/lib/python3.8/site-packages/keras/utils/traceback_utils.py", line 92, in error_handler
>>>     return fn(*args, **kwargs)
>>>
>>>   File "/home/melih/anaconda3/envs/tf-web/lib/python3.8/site-packages/keras/engine/functional.py", line 451, in call
>>>     return self._run_internal_graph(
>>>
>>>   File "/home/melih/anaconda3/envs/tf-web/lib/python3.8/site-packages/keras/engine/functional.py", line 589, in _run_internal_graph
>>>     outputs = node.layer(*args, **kwargs)
>>>
>>>   File "/home/melih/anaconda3/envs/tf-web/lib/python3.8/site-packages/keras/utils/traceback_utils.py", line 64, in error_handler
>>>     return fn(*args, **kwargs)
>>>
>>>   File "/home/melih/anaconda3/envs/tf-web/lib/python3.8/site-packages/keras/engine/base_layer.py", line 1083, in __call__
>>>     outputs = call_fn(inputs, *args, **kwargs)
>>>
>>>   File "/home/melih/anaconda3/envs/tf-web/lib/python3.8/site-packages/keras/utils/traceback_utils.py", line 92, in error_handler
>>>     return fn(*args, **kwargs)
>>>
>>>   File "/home/melih/anaconda3/envs/tf-web/lib/python3.8/site-packages/keras/layers/convolutional.py", line 246, in call
>>>     outputs = self.convolution_op(inputs, self.kernel)
>>>
>>>   File "/home/melih/anaconda3/envs/tf-web/lib/python3.8/site-packages/keras/layers/convolutional.py", line 231, in convolution_op
>>>     return tf.nn.convolution(
>>>